Workbook

Sheet Dashboard
B2: BLACK-SCHOLES OPTIONS PRICING DASHBOARD
B3: Option Pricing · Greeks Analysis · Sensitivity Tables · Payoff Diagrams
B4: Arsh Gulia | FRM Certified | B.A. (Hons.) Business Economics, University of Delhi
B6: MODEL NAVIGATION
B7: 1. Assumptions | C7: Input all parameters: Stock Price, Strike, Vol, Rate, Time. START HERE.
B8: 2. Option Pricer | C8: Live Black-Scholes Call & Put prices with all 5 Greeks calculated.
B9: 3. Sensitivity Tables | C9: How option price and Greeks change across spot prices and volatilities.
B10: 4. Payoff Analysis | C10: P&L diagrams at expiry for long/short call and put strategies.
B11: 5. Greeks Deep-Dive | C11: Individual Greek profiles across strike range with interpretations.
B13: COLOUR CODING CONVENTION
B14: Blue text | C14: Hardcoded inputs — values you change
B15: Black text | C15: Formulas & calculations — do not edit
B16: Green text | C16: Cross-sheet links from Assumptions
B17: Yellow bg | C17: Key input cells requiring your attention
B19: BLACK-SCHOLES MODEL — FORMULAE
B20: Call Price | C20: C = S·N(d₁) − K·e^(−rT)·N(d₂)
B21: Put Price | C21: P = K·e^(−rT)·N(−d₂) − S·N(−d₁)
B22: d₁ | C22: d₁ = [ln(S/K) + (r + σ²/2)·T] / (σ·√T)
B23: d₂ | C23: d₂ = d₁ − σ·√T
B24: Delta (Δ) | C24: Call: N(d₁) | Put: N(d₁) − 1
B25: Gamma (Γ) | C25: N'(d₁) / (S·σ·√T) [same for call and put]
B26: Vega (ν) | C26: S·N'(d₁)·√T [same for call and put, per 1% vol move ÷100]
B27: Theta (Θ) | C27: −[S·N'(d₁)·σ/(2√T)] − r·K·e^(−rT)·N(d₂) [call, per day ÷365]
B28: Rho (ρ) | C28: Call: K·T·e^(−rT)·N(d₂)·0.01 | Put: −K·T·e^(−rT)·N(−d₂)·0.01

Sheet Assumptions
B2: INPUT PARAMETERS — BLACK-SCHOLES MODEL
B3: Change the BLUE cells below. All other sheets update automatically.
B5: A. OPTION PARAMETERS
B6: S — Current Stock Price (₹) | C6: 2500 | D6: e.g. RELIANCE at ₹2,500
B7: K — Strike Price (₹) | C7: 2500 | D7: At-the-money option
B8: σ — Annual Volatility (%) | C8: 0.25 | D8: 25% vol — typical mid-cap India
B9: r — Risk-Free Rate (% p.a.) | C9: 0.065 | D9: ~RBI repo rate proxy
B10: T — Time to Expiry (Years) | C10: 0.25 | D10: 3 months = 0.25 years
B11: q — Dividend Yield (% p.a.) | C11: 0.01 | D11: Set to 0 if no dividend
B13: B. DERIVED INTERMEDIATE VALUES (for transparency)
B14: ln(S/K) | C14: =LN(C6/C7) -> 0 | D14: Natural log of moneyness
B15: σ·√T | C15: =C8*SQRT(C10) -> 0.125 | D15: Volatility scaled to time
B16: d₁ | C16: =(LN(C6/C7)+(C9-C11+C8^2/2)*C10)/(C8*SQRT(C10)) -> 0.1725 | D16: d1 parameter
B17: d₂ = d₁ − σ√T | C17: =C16-C8*SQRT(C10) -> 0.0475 | D17: d2 parameter
B18: N(d₁) [Cumulative] | C18: =NORMSDIST(C16) -> 0.56847777 | D18: Probability d1
B19: N(d₂) [Cumulative] | C19: =NORMSDIST(C17) -> 0.51894263 | D19: Probability d2
B20: N(−d₁) | C20: =1-C18 -> 0.43152223 | D20: 1 - N(d1)
B21: N(−d₂) | C21: =1-C19 -> 0.48105737 | D21: 1 - N(d2)
B22: N'(d₁) [PDF] | C22: =NORMDIST(C16,0,1,FALSE()) -> 0.3930507 | D22: Standard normal density at d1
B23: e^(−rT) | C23: =EXP(-(C9-C11)*C10) -> 0.9863441 | D23: Discount factor
B25: C. SENSITIVITY TABLE RANGES (used in Sensitivity Tables sheet)
B26: Spot Price Min (₹) | C26: =C6*0.7 -> 1750 | D26: 70% of current spot
B27: Spot Price Max (₹) | C27: =C6*1.3 -> 3250 | D27: 130% of current spot
B28: Spot Price Step (₹) | C28: 50 | D28: Increment between spot prices
B29: Volatility Min (%) | C29: 0.1 | D29: 10% vol lower bound
B30: Volatility Max (%) | C30: 0.5 | D30: 50% vol upper bound
B31: Volatility Step (%) | C31: 0.05 | D31: 5% increments

Sheet Option Pricer
B2: OPTION PRICER — BLACK-SCHOLES LIVE PRICING & GREEKS
B3: All values update automatically when Assumptions sheet inputs are changed
B5: A. OPTION PRICES
B6: Metric | C6: CALL Option | D6: Interpretation | F6: PUT Option | G6: Interpretation
B7: Option Price (₹) | C7: =Assumptions!C6*Assumptions!C18*EXP(-Assumptions!C11*Assumptions!C10)-Assumptions!C7*Assumptions!C23*Assumptions!C19 -> 138.00586 | D7: Max amount CALL buyer should pay | E7: =Assumptions!C7*Assumptions!C23*Assumptions!C21-Assumptions!C6*EXP(-Assumptions!C11*Assumptions!C10)*Assumptions!C20 -> 110.1083 | F7: Max amount PUT buyer should pay
B8: Intrinsic Value (₹) | C8: =MAX(Assumptions!C6-Assumptions!C7,0) -> 0 | D8: In-the-money amount (floor = 0) | E8: =MAX(Assumptions!C7-Assumptions!C6,0) -> 0 | F8: In-the-money amount (floor = 0)
B9: Time Value (₹) | C9: =C7-C8 -> 138.00586 | D9: Premium above intrinsic value | E9: =E7-E8 -> 110.1083 | F9: Premium above intrinsic value
B10: Moneyness | C10: =IF(Assumptions!C6>Assumptions!C7,"In-the-Money (ITM)",IF(Assumptions!C6=Assumptions!C7,"At-the-Money (ATM)","Out-of-the-Money (OTM)")) -> At-the-Money (ATM) | D10: Relationship of spot to strike | E10: =IF(Assumptions!C6<Assumptions!C7,"In-the-Money (ITM)",IF(Assumptions!C6=Assumptions!C7,"At-the-Money (ATM)","Out-of-the-Money (OTM)")) -> At-the-Money (ATM) | F10: Relationship of spot to strike
B12: B. THE GREEKS — RISK SENSITIVITIES
B13: Greek | C13: Symbol | D13: CALL Value | E13: PUT Value | F13: Unit | G13: What it Measures | H13: Risk Management Use
B14: Delta | C14: Δ | D14: =Assumptions!C18 -> 0.56847777 | E14: =Assumptions!C18-1 -> -0.43152223 | F14: ₹ per ₹1 move in S | G14: Change in option price per ₹1 rise in stock | J14: Hedge ratio — units of stock to hold per option sold
B15: Gamma | C15: Γ | D15: =Assumptions!C22/(Assumptions!C6*Assumptions!C8*SQRT(Assumptions!C10)) -> 0.0012577623 | E15: =Assumptions!C22/(Assumptions!C6*Assumptions!C8*SQRT(Assumptions!C10)) -> 0.0012577623 | F15: Δ per ₹1 move in S | G15: Rate of change of Delta; acceleration of option value | J15: High Gamma = Delta hedges need frequent rebalancing
B16: Vega | C16: ν | D16: =Assumptions!C6*Assumptions!C22*SQRT(Assumptions!C10)/100 -> 4.9131338 | E16: =Assumptions!C6*Assumptions!C22*SQRT(Assumptions!C10)/100 -> 4.9131338 | F16: ₹ per 1% vol move | G16: Sensitivity to implied volatility (per 1% change) | J16: Long options have positive Vega — profit from vol spikes
B17: Theta | C17: Θ | D17: =(-(Assumptions!C6*Assumptions!C22*Assumptions!C8)/(2*SQRT(Assumptions!C10))-(Assumptions!C9-Assumptions!C11)*Assumptions!C7*Assumptions!C23*Assumptions!C19)/365 -> -0.86585449 | E17: =(-(Assumptions!C6*Assumptions!C22*Assumptions!C8)/(2*SQRT(Assumptions!C10))+(Assumptions!C9-Assumptions!C11)*Assumptions!C7*Assumptions!C23*Assumptions!C21)/365 -> -0.49428651 | F17: ₹ per calendar day | G17: Time decay — option loses this value each day | J17: Theta is negative for buyers — time erodes option value
B18: Rho | C18: ρ | D18: =Assumptions!C7*Assumptions!C10*Assumptions!C23*Assumptions!C19*0.01 -> 3.1991 | E18: =-Assumptions!C7*Assumptions!C10*Assumptions!C23*Assumptions!C21*0.01 -> -2.9655506 | F18: ₹ per 1% rate move | G18: Sensitivity to risk-free interest rate | J18: Least important Greek in short-dated equity options
B20: C. PUT-CALL PARITY VERIFICATION
B21: C + K·e^(−rT) | E21: = | F21: P + S·e^(−qT) | I21: Difference
B22: Left Side (C + Ke^-rT) | C22: =C7+Assumptions!C7*Assumptions!C23 -> 2603.8661 | E22: vs | F22: Right Side (P + Se^-qT) | G22: =E7+Assumptions!C6*EXP(-Assumptions!C11*Assumptions!C10) -> 2603.8661 | I22: =ABS(C22-G22) -> 0 | J22: Difference should be ~₹0.00 — confirms model accuracy

Sheet Sensitivity Tables
B2: SENSITIVITY ANALYSIS — OPTION PRICES & DELTA ACROSS SPOT AND VOLATILITY
B3: Shows how Call/Put prices and Delta change as Spot Price (rows) and Volatility (columns) vary simultaneously
B5: CALL OPTION PRICE (₹) — Spot vs Volatility
B6: Spot ↓ Vol → | C6: 10% | D6: 15% | E6: 20% | F6: 25% | G6: 30% | H6: 35% | I6: 40% | J6: 45% | K6: 50%
B7: 1750 | C7: =1750*EXP(-Assumptions!$C$11*Assumptions!$C$10)*NORMSDIST((LN(1750/Assumptions!$C$7)+(Assumptions!$C$9-Assumptions!$C$11+0.1^2/2)*Assumptions!$C$10)/(0.1*SQRT(Assumptions!$C$10)))-Assumptions!$C$7*EXP(-Assumptions!$C$9*Assumptions!$C$10)*NORMSDIST(((LN(1750/Assumptions!$C$7)+(Assumptions!$C$9-Assumptions!$C$11+0.1^2/2)*Assumptions!$C$10)/(0.1*SQRT(Assumptions!$C$10)))-0.1*SQRT(Assumptions!$C$10)) -> 5.0517131e-11 | D7: =1750*EXP(-Assumptions!$C$11*Assumptions!$C$10)*NORMSDIST((LN(1750/Assumptions!$C$7)+(Assumptions!$C$9-Assumptions!$C$11+0.15^2/2)*Assumptions!$C$10)/(0.15*SQRT(Assumptions!$C$10)))-Assumptions!$C$7*EXP(-Assumptions!$C$9*Assumptions!$C$10)*NORMSDIST(((LN(1750/Assumptions!$C$7)+(Assumptions!$C$9-Assumptions!$C$11+0.15^2/2)*Assumptions!$C$10)/(0.15*SQRT(Assumptions!$C$10)))-0.15*SQRT(Assumptions!$C$10)) -> 7.5488997e-05 | E7: =1750*EXP(-Assumptions!$C$11*Assumptions!$C$10)*NORMSDIST((LN(1750/Assumptions!$C$7)+(Assumptions!$C$9-Assumptions!$C$11+0.2^2/2)*Assumptions!$C$10)/(0.2*SQRT(Assumptions!$C$10)))-Assumptions!$C$7*EXP(-Assumptions!$C$9*Assumptions!$C$10)*NORMSDIST(((LN(1750/Assumptions!$C$7)+(Assumptions!$C$9-Assumptions!$C$11+0.2^2/2)*Assumptions!$C$10)/(0.2*SQRT(Assumptions!$C$10)))-0.2*SQRT(Assumptions!$C$10)) -> 0.016002861 | F7: =1750*EXP(-Assumptions!$C$11*Assumptions!$C$10)*NORMSDIST((LN(1750/Assumptions!$C$7)+(Assumptions!$C$9-Assumptions!$C$11+0.25^2/2)*Assumptions!$C$10)/(0.25*SQRT(Assumptions!$C$10)))-Assumptions!$C$7*EXP(-Assumptions!$C$9*Assumptions!$C$10)*NORMSDIST(((LN(1750/Assumptions!$C$7)+(Assumptions!$C$9-Assumptions!$C$11+0.25^2/2)*Assumptions!$C$10)/(0.25*SQRT(Assumptions!$C$10)))-0.25*SQRT(Assumptions!$C$10)) -> 0.23766239 | G7: =1750*EXP(-Assumptions!$C$11*Assumptions!$C$10)*NORMSDIST((LN(1750/Assumptions!$C$7)+(Assumptions!$C$9-Assumptions!$C$11+0.3^2/2)*Assumptions!$C$10)/(0.3*SQRT(Assumptions!$C$10)))-Assumptions!$C$7*EXP(-Assumptions!$C$9*Assumptions!$C$10)*NORMSDIST(((LN(1750/Assumptions!$C$7)+(Assumptions!$C$9-Assumptions!$C$11+0.3^2/2)*Assumptions!$C$10)/(0.3*SQRT(Assumptions!$C$10)))-0.3*SQRT(Assumptions!$C$10)) -> 1.1823457 | H7: =1750*EXP(-Assumptions!$C$11*Assumptions!$C$10)*NORMSDIST((LN(1750/Assumptions!$C$7)+(Assumptions!$C$9-Assumptions!$C$11+0.35^2/2)*Assumptions!$C$10)/(0.35*SQRT(Assumptions!$C$10)))-Assumptions!$C$7*EXP(-Assumptions!$C$9*Assumptions!$C$10)*NORMSDIST(((LN(1750/Assumptions!$C$7)+(Assumptions!$C$9-Assumptions!$C$11+0.35^2/2)*Assumptions!$C$10)/(0.35*SQRT(Assumptions!$C$10)))-0.35*SQRT(Assumptions!$C$10)) -> 3.4186436 | I7: =1750*EXP(-Assumptions!$C$11*Assumptions!$C$10)*NORMSDIST((LN(1750/Assumptions!$C$7)+(Assumptions!$C$9-Assumptions!$C$11+0.4^2/2)*Assumptions!$C$10)/(0.4*SQRT(Assumptions!$C$10)))-Assumptions!$C$7*EXP(-Assumptions!$C$9*Assumptions!$C$10)*NORMSDIST(((LN(1750/Assumptions!$C$7)+(Assumptions!$C$9-Assumptions!$C$11+0.4^2/2)*Assumptions!$C$10)/(0.4*SQRT(Assumptions!$C$10)))-0.4*SQRT(Assumptions!$C$10)) -> 7.2855018 | J7: =1750*EXP(-Assumptions!$C$11*Assumptions!$C$10)*NORMSDIST((LN(1750/Assumptions!$C$7)+(Assumptions!$C$9-Assumptions!$C$11+0.45^2/2)*Assumptions!$C$10)/(0.45*SQRT(Assumptions!$C$10)))-Assumptions!$C$7*EXP(-Assumptions!$C$9*Assumptions!$C$10)*NORMSDIST(((LN(1750/Assumptions!$C$7)+(Assumptions!$C$9-Assumptions!$C$11+0.45^2/2)*Assumptions!$C$10)/(0.45*SQRT(Assumptions!$C$10)))-0.45*SQRT(Assumptions!$C$10)) -> 12.870736 | K7: =1750*EXP(-Assumptions!$C$11*Assumptions!$C$10)*NORMSDIST((LN(1750/Assumptions!$C$7)+(Assumptions!$C$9-Assumptions!$C$11+0.5^2/2)*Assumptions!$C$10)/(0.5*SQRT(Assumptions!$C$10)))-Assumptions!$C$7*EXP(-Assumptions!$C$9*Assumptions!$C$10)*NORMSDIST(((LN(1750/Assumptions!$C$7)+(Assumptions!$C$9-Assumptions!$C$11+0.5^2/2)*Assumptions!$C$10)/(0.5*SQRT(Assumptions!$C$10)))-0.5*SQRT(Assumptions!$C$10)) -> 20.100005
B8: 1800 | C8: =1800*EXP(-Assumptions!$C$11*Assumptions!$C$10)*NORMSDIST((LN(1800/Assumptions!$C$7)+(Assumptions!$C$9-Assumptions!$C$11+0.1^2/2)*Assumptions!$C$10)/(0.1*SQRT(Assumptions!$C$10)))-Assumptions!$C$7*EXP(-Assumptions!$C$9*Assumptions!$C$10)*NORMSDIST(((LN(1800/Assumptions!$C$7)+(Assumptions!$C$9-Assumptions!$C$11+0.1^2/2)*Assumptions!$C$10)/(0.1*SQRT(Assumptions!$C$10)))-0.1*SQRT(Assumptions!$C$10)) -> 2.4478926e-09 | D8: =1800*EXP(-Assumptions!$C$11*Assumptions!$C$10)*NORMSDIST((LN(1800/Assumptions!$C$7)+(Assumptions!$C$9-Assumptions!$C$11+0.15^2/2)*Assumptions!$C$10)/(0.15*SQRT(Assumptions!$C$10)))-Assumptions!$C$7*EXP(-Assumptions!$C$9*Assumptions!$C$10)*NORMSDIST(((LN(1800/Assumptions!$C$7)+(Assumptions!$C$9-Assumptions!$C$11+0.15^2/2)*Assumptions!$C$10)/(0.15*SQRT(Assumptions!$C$10)))-0.15*SQRT(Assumptions!$C$10)) -> 0.00046230084 | E8: =1800*EXP(-Assumptions!$C$11*Assumptions!$C$10)*NORMSDIST((LN(1800/Assumptions!$C$7)+(Assumptions!$C$9-Assumptions!$C$11+0.2^2/2)*Assumptions!$C$10)/(0.2*SQRT(Assumptions!$C$10)))-Assumptions!$C$7*EXP(-Assumptions!$C$9*Assumptions!$C$10)*NORMSDIST(((LN(1800/Assumptions!$C$7)+(Assumptions!$C$9-Assumptions!$C$11+0.2^2/2)*Assumptions!$C$10)/(0.2*SQRT(Assumptions!$C$10)))-0.2*SQRT(Assumptions!$C$10)) -> 0.047183334 | F8: =1800*EXP(-Assumptions!$C$11*Assumptions!$C$10)*NORMSDIST((LN(1800/Assumptions!$C$7)+(Assumptions!$C$9-Assumptions!$C$11+0.25^2/2)*Assumptions!$C$10)/(0.25*SQRT(Assumptions!$C$10)))-Assumptions!$C$7*EXP(-Assumptions!$C$9*Assumptions!$C$10)*NORMSDIST(((LN(1800/Assumptions!$C$7)+(Assumptions!$C$9-Assumptions!$C$11+0.25^2/2)*Assumptions!$C$10)/(0.25*SQRT(Assumptions!$C$10)))-0.25*SQRT(Assumptions!$C$10)) -> 0.49698109 | G8: =1800*EXP(-Assumptions!$C$11*Assumptions!$C$10)*NORMSDIST((LN(1800/Assumptions!$C$7)+(Assumptions!$C$9-Assumptions!$C$11+0.3^2/2)*Assumptions!$C$10)/(0.3*SQRT(Assumptions!$C$10)))-Assumptions!$C$7*EXP(-Assumptions!$C$9*Assumptions!$C$10)*NORMSDIST(((LN(1800/Assumptions!$C$7)+(Assumptions!$C$9-Assumptions!$C$11+0.3^2/2)*Assumptions!$C$10)/(0.3*SQRT(Assumptions!$C$10)))-0.3*SQRT(Assumptions!$C$10)) -> 2.0436678 | H8: =1800*EXP(-Assumptions!$C$11*Assumptions!$C$10)*NORMSDIST((LN(1800/Assumptions!$C$7)+(Assumptions!$C$9-Assumptions!$C$11+0.35^2/2)*Assumptions!$C$10)/(0.35*SQRT(Assumptions!$C$10)))-Assumptions!$C$7*EXP(-Assumptions!$C$9*Assumptions!$C$10)*NORMSDIST(((LN(1800/Assumptions!$C$7)+(Assumptions!$C$9-Assumptions!$C$11+0.35^2/2)*Assumptions!$C$10)/(0.35*SQRT(Assumptions!$C$10)))-0.35*SQRT(Assumptions!$C$10)) -> 5.2533161 | I8: =1800*EXP(-Assumptions!$C$11*Assumptions!$C$10)*NORMSDIST((LN(1800/Assumptions!$C$7)+(Assumptions!$C$9-Assumptions!$C$11+0.4^2/2)*Assumptions!$C$10)/(0.4*SQRT(Assumptions!$C$10)))-Assumptions!$C$7*EXP(-Assumptions!$C$9*Assumptions!$C$10)*NORMSDIST(((LN(1800/Assumptions!$C$7)+(Assumptions!$C$9-Assumptions!$C$11+0.4^2/2)*Assumptions!$C$10)/(0.4*SQRT(Assumptions!$C$10)))-0.4*SQRT(Assumptions!$C$10)) -> 10.351072 | J8: =1800*EXP(-Assumptions!$C$11*Assumptions!$C$10)*NORMSDIST((LN(1800/Assumptions!$C$7)+(Assumptions!$C$9-Assumptions!$C$11+0.45^2/2)*Assumptions!$C$10)/(0.45*SQRT(Assumptions!$C$10)))-Assumptions!$C$7*EXP(-Assumptions!$C$9*Assumptions!$C$10)*NORMSDIST(((LN(1800/Assumptions!$C$7)+(Assumptions!$C$9-Assumptions!$C$11+0.45^2/2)*Assumptions!$C$10)/(0.45*SQRT(Assumptions!$C$10)))-0.45*SQRT(Assumptions!$C$10)) -> 17.30243 | K8: =1800*EXP(-Assumptions!$C$11*Assumptions!$C$10)*NORMSDIST((LN(1800/Assumptions!$C$7)+(Assumptions!$C$9-Assumptions!$C$11+0.5^2/2)*Assumptions!$C$10)/(0.5*SQRT(Assumptions!$C$10)))-Assumptions!$C$7*EXP(-Assumptions!$C$9*Assumptions!$C$10)*NORMSDIST(((LN(1800/Assumptions!$C$7)+(Assumptions!$C$9-Assumptions!$C$11+0.5^2/2)*Assumptions!$C$10)/(0.5*SQRT(Assumptions!$C$10)))-0.5*SQRT(Assumptions!$C$10)) -> 25.941807
B9: 1850 | C9: =1850*EXP(-Assumptions!$C$11*Assumptions!$C$10)*NORMSDIST((LN(1850/Assumptions!$C$7)+(Assumptions!$C$9-Assumptions!$C$11+0.1^2/2)*Assumptions!$C$10)/(0.1*SQRT(Assumptions!$C$10)))-Assumptions!$C$7*EXP(-Assumptions!$C$9*Assumptions!$C$10)*NORMSDIST(((LN(1850/Assumptions!$C$7)+(Assumptions!$C$9-Assumptions!$C$11+0.1^2/2)*Assumptions!$C$10)/(0.1*SQRT(Assumptions!$C$10)))-0.1*SQRT(Assumptions!$C$10)) -> 7.9655865e-08 | D9: =1850*EXP(-Assumptions!$C$11*Assumptions!$C$10)*NORMSDIST((LN(1850/Assumptions!$C$7)+(Assumptions!$C$9-Assumptions!$C$11+0.15^2/2)*Assumptions!$C$10)/(0.15*SQRT(Assumptions!$C$10)))-Assumptions!$C$7*EXP(-Assumptions!$C$9*Assumptions!$C$10)*NORMSDIST(((LN(1850/Assumptions!$C$7)+(Assumptions!$C$9-Assumptions!$C$11+0.15^2/2)*Assumptions!$C$10)/(0.15*SQRT(Assumptions!$C$10)))-0.15*SQRT(Assumptions!$C$10)) -> 0.0023778842 | E9: =1850*EXP(-Assumptions!$C$11*Assumptions!$C$10)*NORMSDIST((LN(1850/Assumptions!$C$7)+(Assumptions!$C$9-Assumptions!$C$11+0.2^2/2)*Assumptions!$C$10)/(0.2*SQRT(Assumptions!$C$10)))-Assumptions!$C$7*EXP(-Assumptions!$C$9*Assumptions!$C$10)*NORMSDIST(((LN(1850/Assumptions!$C$7)+(Assumptions!$C$9-Assumptions!$C$11+0.2^2/2)*Assumptions!$C$10)/(0.2*SQRT(Assumptions!$C$10)))-0.2*SQRT(Assumptions!$C$10)) -> 0.12623789 | F9: =1850*EXP(-Assumptions!$C$11*Assumptions!$C$10)*NORMSDIST((LN(1850/Assumptions!$C$7)+(Assumptions!$C$9-Assumptions!$C$11+0.25^2/2)*Assumptions!$C$10)/(0.25*SQRT(Assumptions!$C$10)))-Assumptions!$C$7*EXP(-Assumptions!$C$9*Assumptions!$C$10)*NORMSDIST(((LN(1850/Assumptions!$C$7)+(Assumptions!$C$9-Assumptions!$C$11+0.25^2/2)*Assumptions!$C$10)/(0.25*SQRT(Assumptions!$C$10)))-0.25*SQRT(Assumptions!$C$10)) -> 0.97689116 | G9: =1850*EXP(-Assumptions!$C$11*Assumptions!$C$10)*NORMSDIST((LN(1850/Assumptions!$C$7)+(Assumptions!$C$9-Assumptions!$C$11+0.3^2/2)*Assumptions!$C$10)/(0.3*SQRT(Assumptions!$C$10)))-Assumptions!$C$7*EXP(-Assumptions!$C$9*Assumptions!$C$10)*NORMSDIST(((LN(1850/Assumptions!$C$7)+(Assumptions!$C$9-Assumptions!$C$11+0.3^2/2)*Assumptions!$C$10)/(0.3*SQRT(Assumptions!$C$10)))-0.3*SQRT(Assumptions!$C$10)) -> 3.3837866 | H9: =1850*EXP(-Assumptions!$C$11*Assumptions!$C$10)*NORMSDIST((LN(1850/Assumptions!$C$7)+(Assumptions!$C$9-Assumptions!$C$11+0.35^2/2)*Assumptions!$C$10)/(0.35*SQRT(Assumptions!$C$10)))-Assumptions!$C$7*EXP(-Assumptions!$C$9*Assumptions!$C$10)*NORMSDIST(((LN(1850/Assumptions!$C$7)+(Assumptions!$C$9-Assumptions!$C$11+0.35^2/2)*Assumptions!$C$10)/(0.35*SQRT(Assumptions!$C$10)))-0.35*SQRT(Assumptions!$C$10)) -> 7.8202577 | I9: =1850*EXP(-Assumptions!$C$11*Assumptions!$C$10)*NORMSDIST((LN(1850/Assumptions!$C$7)+(Assumptions!$C$9-Assumptions!$C$11+0.4^2/2)*Assumptions!$C$10)/(0.4*SQRT(Assumptions!$C$10)))-Assumptions!$C$7*EXP(-Assumptions!$C$9*Assumptions!$C$10)*NORMSDIST(((LN(1850/Assumptions!$C$7)+(Assumptions!$C$9-Assumptions!$C$11+0.4^2/2)*Assumptions!$C$10)/(0.4*SQRT(Assumptions!$C$10)))-0.4*SQRT(Assumptions!$C$10)) -> 14.350055 | J9: =1850*EXP(-Assumptions!$C$11*Assumptions!$C$10)*NORMSDIST((LN(1850/Assumptions!$C$7)+(Assumptions!$C$9-Assumptions!$C$11+0.45^2/2)*Assumptions!$C$10)/(0.45*SQRT(Assumptions!$C$10)))-Assumptions!$C$7*EXP(-Assumptions!$C$9*Assumptions!$C$10)*NORMSDIST(((LN(1850/Assumptions!$C$7)+(Assumptions!$C$9-Assumptions!$C$11+0.45^2/2)*Assumptions!$C$10)/(0.45*SQRT(Assumptions!$C$10)))-0.45*SQRT(Assumptions!$C$10)) -> 22.807874 | K9: =1850*EXP(-Assumptions!$C$11*Assumptions!$C$10)*NORMSDIST((LN(1850/Assumptions!$C$7)+(Assumptions!$C$9-Assumptions!$C$11+0.5^2/2)*Assumptions!$C$10)/(0.5*SQRT(Assumptions!$C$10)))-Assumptions!$C$7*EXP(-Assumptions!$C$9*Assumptions!$C$10)*NORMSDIST(((LN(1850/Assumptions!$C$7)+(Assumptions!$C$9-Assumptions!$C$11+0.5^2/2)*Assumptions!$C$10)/(0.5*SQRT(Assumptions!$C$10)))-0.5*SQRT(Assumptions!$C$10)) -> 32.945342
B10: 1900 | C10: =1900*EXP(-Assumptions!$C$11*Assumptions!$C$10)*NORMSDIST((LN(1900/Assumptions!$C$7)+(Assumptions!$C$9-Assumptions!$C$11+0.1^2/2)*Assumptions!$C$10)/(0.1*SQRT(Assumptions!$C$10)))-Assumptions!$C$7*EXP(-Assumptions!$C$9*Assumptions!$C$10)*NORMSDIST(((LN(1900/Assumptions!$C$7)+(Assumptions!$C$9-Assumptions!$C$11+0.1^2/2)*Assumptions!$C$10)/(0.1*SQRT(Assumptions!$C$10)))-0.1*SQRT(Assumptions!$C$10)) -> 1.7952019e-06 | D10: =1900*EXP(-Assumptions!$C$11*Assumptions!$C$10)*NORMSDIST((LN(1900/Assumptions!$C$7)+(Assumptions!$C$9-Assumptions!$C$11+0.15^2/2)*Assumptions!$C$10)/(0.15*SQRT(Assumptions!$C$10)))-Assumptions!$C$7*EXP(-Assumptions!$C$9*Assumptions!$C$10)*NORMSDIST(((LN(1900/Assumptions!$C$7)+(Assumptions!$C$9-Assumptions!$C$11+0.15^2/2)*Assumptions!$C$10)/(0.15*SQRT(Assumptions!$C$10)))-0.15*SQRT(Assumptions!$C$10)) -> 0.010416679 | E10: =1900*EXP(-Assumptions!$C$11*Assumptions!$C$10)*NORMSDIST((LN(1900/Assumptions!$C$7)+(Assumptions!$C$9-Assumptions!$C$11+0.2^2/2)*Assumptions!$C$10)/(0.2*SQRT(Assumptions!$C$10)))-Assumptions!$C$7*EXP(-Assumptions!$C$9*Assumptions!$C$10)*NORMSDIST(((LN(1900/Assumptions!$C$7)+(Assumptions!$C$9-Assumptions!$C$11+0.2^2/2)*Assumptions!$C$10)/(0.2*SQRT(Assumptions!$C$10)))-0.2*SQRT(Assumptions!$C$10)) -> 0.30890004 | F10: =1900*EXP(-Assumptions!$C$11*Assumptions!$C$10)*NORMSDIST((LN(1900/Assumptions!$C$7)+(Assumptions!$C$9-Assumptions!$C$11+0.25^2/2)*Assumptions!$C$10)/(0.25*SQRT(Assumptions!$C$10)))-Assumptions!$C$7*EXP(-Assumptions!$C$9*Assumptions!$C$10)*NORMSDIST(((LN(1900/Assumptions!$C$7)+(Assumptions!$C$9-Assumptions!$C$11+0.25^2/2)*Assumptions!$C$10)/(0.25*SQRT(Assumptions!$C$10)))-0.25*SQRT(Assumptions!$C$10)) -> 1.8141047 | G10: =1900*EXP(-Assumptions!$C$11*Assumptions!$C$10)*NORMSDIST((LN(1900/Assumptions!$C$7)+(Assumptions!$C$9-Assumptions!$C$11+0.3^2/2)*Assumptions!$C$10)/(0.3*SQRT(Assumptions!$C$10)))-Assumptions!$C$7*EXP(-Assumptions!$C$9*Assumptions!$C$10)*NORMSDIST(((LN(1900/Assumptions!$C$7)+(Assumptions!$C$9-Assumptions!$C$11+0.3^2/2)*Assumptions!$C$10)/(0.3*SQRT(Assumptions!$C$10)))-0.3*SQRT(Assumptions!$C$10)) -> 5.3855769 | H10: =1900*EXP(-Assumptions!$C$11*Assumptions!$C$10)*NORMSDIST((LN(1900/Assumptions!$C$7)+(Assumptions!$C$9-Assumptions!$C$11+0.35^2/2)*Assumptions!$C$10)/(0.35*SQRT(Assumptions!$C$10)))-Assumptions!$C$7*EXP(-Assumptions!$C$9*Assumptions!$C$10)*NORMSDIST(((LN(1900/Assumptions!$C$7)+(Assumptions!$C$9-Assumptions!$C$11+0.35^2/2)*Assumptions!$C$10)/(0.35*SQRT(Assumptions!$C$10)))-0.35*SQRT(Assumptions!$C$10)) -> 11.306323 | I10: =1900*EXP(-Assumptions!$C$11*Assumptions!$C$10)*NORMSDIST((LN(1900/Assumptions!$C$7)+(Assumptions!$C$9-Assumptions!$C$11+0.4^2/2)*Assumptions!$C$10)/(0.4*SQRT(Assumptions!$C$10)))-Assumptions!$C$7*EXP(-Assumptions!$C$9*Assumptions!$C$10)*NORMSDIST(((LN(1900/Assumptions!$C$7)+(Assumptions!$C$9-Assumptions!$C$11+0.4^2/2)*Assumptions!$C$10)/(0.4*SQRT(Assumptions!$C$10)))-0.4*SQRT(Assumptions!$C$10)) -> 19.449488 | J10: =1900*EXP(-Assumptions!$C$11*Assumptions!$C$10)*NORMSDIST((LN(1900/Assumptions!$C$7)+(Assumptions!$C$9-Assumptions!$C$11+0.45^2/2)*Assumptions!$C$10)/(0.45*SQRT(Assumptions!$C$10)))-Assumptions!$C$7*EXP(-Assumptions!$C$9*Assumptions!$C$10)*NORMSDIST(((LN(1900/Assumptions!$C$7)+(Assumptions!$C$9-Assumptions!$C$11+0.45^2/2)*Assumptions!$C$10)/(0.45*SQRT(Assumptions!$C$10)))-0.45*SQRT(Assumptions!$C$10)) -> 29.525886 | K10: =1900*EXP(-Assumptions!$C$11*Assumptions!$C$10)*NORMSDIST((LN(1900/Assumptions!$C$7)+(Assumptions!$C$9-Assumptions!$C$11+0.5^2/2)*Assumptions!$C$10)/(0.5*SQRT(Assumptions!$C$10)))-Assumptions!$C$7*EXP(-Assumptions!$C$9*Assumptions!$C$10)*NORMSDIST(((LN(1900/Assumptions!$C$7)+(Assumptions!$C$9-Assumptions!$C$11+0.5^2/2)*Assumptions!$C$10)/(0.5*SQRT(Assumptions!$C$10)))-0.5*SQRT(Assumptions!$C$10)) -> 41.22097
B11: 1950 | C11: =1950*EXP(-Assumptions!$C$11*Assumptions!$C$10)*NORMSDIST((LN(1950/Assumptions!$C$7)+(Assumptions!$C$9-Assumptions!$C$11+0.1^2/2)*Assumptions!$C$10)/(0.1*SQRT(Assumptions!$C$10)))-Assumptions!$C$7*EXP(-Assumptions!$C$9*Assumptions!$C$10)*NORMSDIST(((LN(1950/Assumptions!$C$7)+(Assumptions!$C$9-Assumptions!$C$11+0.1^2/2)*Assumptions!$C$10)/(0.1*SQRT(Assumptions!$C$10)))-0.1*SQRT(Assumptions!$C$10)) -> 2.8825826e-05 | D11: =1950*EXP(-Assumptions!$C$11*Assumptions!$C$10)*NORMSDIST((LN(1950/Assumptions!$C$7)+(Assumptions!$C$9-Assumptions!$C$11+0.15^2/2)*Assumptions!$C$10)/(0.15*SQRT(Assumptions!$C$10)))-Assumptions!$C$7*EXP(-Assumptions!$C$9*Assumptions!$C$10)*NORMSDIST(((LN(1950/Assumptions!$C$7)+(Assumptions!$C$9-Assumptions!$C$11+0.15^2/2)*Assumptions!$C$10)/(0.15*SQRT(Assumptions!$C$10)))-0.15*SQRT(Assumptions!$C$10)) -> 0.039363843 | E11: =1950*EXP(-Assumptions!$C$11*Assumptions!$C$10)*NORMSDIST((LN(1950/Assumptions!$C$7)+(Assumptions!$C$9-Assumptions!$C$11+0.2^2/2)*Assumptions!$C$10)/(0.2*SQRT(Assumptions!$C$10)))-Assumptions!$C$7*EXP(-Assumptions!$C$9*Assumptions!$C$10)*NORMSDIST(((LN(1950/Assumptions!$C$7)+(Assumptions!$C$9-Assumptions!$C$11+0.2^2/2)*Assumptions!$C$10)/(0.2*SQRT(Assumptions!$C$10)))-0.2*SQRT(Assumptions!$C$10)) -> 0.69631666 | F11: =1950*EXP(-Assumptions!$C$11*Assumptions!$C$10)*NORMSDIST((LN(1950/Assumptions!$C$7)+(Assumptions!$C$9-Assumptions!$C$11+0.25^2/2)*Assumptions!$C$10)/(0.25*SQRT(Assumptions!$C$10)))-Assumptions!$C$7*EXP(-Assumptions!$C$9*Assumptions!$C$10)*NORMSDIST(((LN(1950/Assumptions!$C$7)+(Assumptions!$C$9-Assumptions!$C$11+0.25^2/2)*Assumptions!$C$10)/(0.25*SQRT(Assumptions!$C$10)))-0.25*SQRT(Assumptions!$C$10)) -> 3.1973113 | G11: =1950*EXP(-Assumptions!$C$11*Assumptions!$C$10)*NORMSDIST((LN(1950/Assumptions!$C$7)+(Assumptions!$C$9-Assumptions!$C$11+0.3^2/2)*Assumptions!$C$10)/(0.3*SQRT(Assumptions!$C$10)))-Assumptions!$C$7*EXP(-Assumptions!$C$9*Assumptions!$C$10)*NORMSDIST(((LN(1950/Assumptions!$C$7)+(Assumptions!$C$9-Assumptions!$C$11+0.3^2/2)*Assumptions!$C$10)/(0.3*SQRT(Assumptions!$C$10)))-0.3*SQRT(Assumptions!$C$10)) -> 8.2656283 | H11: =1950*EXP(-Assumptions!$C$11*Assumptions!$C$10)*NORMSDIST((LN(1950/Assumptions!$C$7)+(Assumptions!$C$9-Assumptions!$C$11+0.35^2/2)*Assumptions!$C$10)/(0.35*SQRT(Assumptions!$C$10)))-Assumptions!$C$7*EXP(-Assumptions!$C$9*Assumptions!$C$10)*NORMSDIST(((LN(1950/Assumptions!$C$7)+(Assumptions!$C$9-Assumptions!$C$11+0.35^2/2)*Assumptions!$C$10)/(0.35*SQRT(Assumptions!$C$10)))-0.35*SQRT(Assumptions!$C$10)) -> 15.912598 | I11: =1950*EXP(-Assumptions!$C$11*Assumptions!$C$10)*NORMSDIST((LN(1950/Assumptions!$C$7)+(Assumptions!$C$9-Assumptions!$C$11+0.4^2/2)*Assumptions!$C$10)/(0.4*SQRT(Assumptions!$C$10)))-Assumptions!$C$7*EXP(-Assumptions!$C$9*Assumptions!$C$10)*NORMSDIST(((LN(1950/Assumptions!$C$7)+(Assumptions!$C$9-Assumptions!$C$11+0.4^2/2)*Assumptions!$C$10)/(0.4*SQRT(Assumptions!$C$10)))-0.4*SQRT(Assumptions!$C$10)) -> 25.817667 | J11: =1950*EXP(-Assumptions!$C$11*Assumptions!$C$10)*NORMSDIST((LN(1950/Assumptions!$C$7)+(Assumptions!$C$9-Assumptions!$C$11+0.45^2/2)*Assumptions!$C$10)/(0.45*SQRT(Assumptions!$C$10)))-Assumptions!$C$7*EXP(-Assumptions!$C$9*Assumptions!$C$10)*NORMSDIST(((LN(1950/Assumptions!$C$7)+(Assumptions!$C$9-Assumptions!$C$11+0.45^2/2)*Assumptions!$C$10)/(0.45*SQRT(Assumptions!$C$10)))-0.45*SQRT(Assumptions!$C$10)) -> 37.58958 | K11: =1950*EXP(-Assumptions!$C$11*Assumptions!$C$10)*NORMSDIST((LN(1950/Assumptions!$C$7)+(Assumptions!$C$9-Assumptions!$C$11+0.5^2/2)*Assumptions!$C$10)/(0.5*SQRT(Assumptions!$C$10)))-Assumptions!$C$7*EXP(-Assumptions!$C$9*Assumptions!$C$10)*NORMSDIST(((LN(1950/Assumptions!$C$7)+(Assumptions!$C$9-Assumptions!$C$11+0.5^2/2)*Assumptions!$C$10)/(0.5*SQRT(Assumptions!$C$10)))-0.5*SQRT(Assumptions!$C$10)) -> 50.870285
B12: 2000 | C12: =2000*EXP(-Assumptions!$C$11*Assumptions!$C$10)*NORMSDIST((LN(2000/Assumptions!$C$7)+(Assumptions!$C$9-Assumptions!$C$11+0.1^2/2)*Assumptions!$C$10)/(0.1*SQRT(Assumptions!$C$10)))-Assumptions!$C$7*EXP(-Assumptions!$C$9*Assumptions!$C$10)*NORMSDIST(((LN(2000/Assumptions!$C$7)+(Assumptions!$C$9-Assumptions!$C$11+0.1^2/2)*Assumptions!$C$10)/(0.1*SQRT(Assumptions!$C$10)))-0.1*SQRT(Assumptions!$C$10)) -> 0.00033851924 | D12: =2000*EXP(-Assumptions!$C$11*Assumptions!$C$10)*NORMSDIST((LN(2000/Assumptions!$C$7)+(Assumptions!$C$9-Assumptions!$C$11+0.15^2/2)*Assumptions!$C$10)/(0.15*SQRT(Assumptions!$C$10)))-Assumptions!$C$7*EXP(-Assumptions!$C$9*Assumptions!$C$10)*NORMSDIST(((LN(2000/Assumptions!$C$7)+(Assumptions!$C$9-Assumptions!$C$11+0.15^2/2)*Assumptions!$C$10)/(0.15*SQRT(Assumptions!$C$10)))-0.15*SQRT(Assumptions!$C$10)) -> 0.12984511 | E12: =2000*EXP(-Assumptions!$C$11*Assumptions!$C$10)*NORMSDIST((LN(2000/Assumptions!$C$7)+(Assumptions!$C$9-Assumptions!$C$11+0.2^2/2)*Assumptions!$C$10)/(0.2*SQRT(Assumptions!$C$10)))-Assumptions!$C$7*EXP(-Assumptions!$C$9*Assumptions!$C$10)*NORMSDIST(((LN(2000/Assumptions!$C$7)+(Assumptions!$C$9-Assumptions!$C$11+0.2^2/2)*Assumptions!$C$10)/(0.2*SQRT(Assumptions!$C$10)))-0.2*SQRT(Assumptions!$C$10)) -> 1.4555925 | F12: =2000*EXP(-Assumptions!$C$11*Assumptions!$C$10)*NORMSDIST((LN(2000/Assumptions!$C$7)+(Assumptions!$C$9-Assumptions!$C$11+0.25^2/2)*Assumptions!$C$10)/(0.25*SQRT(Assumptions!$C$10)))-Assumptions!$C$7*EXP(-Assumptions!$C$9*Assumptions!$C$10)*NORMSDIST(((LN(2000/Assumptions!$C$7)+(Assumptions!$C$9-Assumptions!$C$11+0.25^2/2)*Assumptions!$C$10)/(0.25*SQRT(Assumptions!$C$10)))-0.25*SQRT(Assumptions!$C$10)) -> 5.3708766 | G12: =2000*EXP(-Assumptions!$C$11*Assumptions!$C$10)*NORMSDIST((LN(2000/Assumptions!$C$7)+(Assumptions!$C$9-Assumptions!$C$11+0.3^2/2)*Assumptions!$C$10)/(0.3*SQRT(Assumptions!$C$10)))-Assumptions!$C$7*EXP(-Assumptions!$C$9*Assumptions!$C$10)*NORMSDIST(((LN(2000/Assumptions!$C$7)+(Assumptions!$C$9-Assumptions!$C$11+0.3^2/2)*Assumptions!$C$10)/(0.3*SQRT(Assumptions!$C$10)))-0.3*SQRT(Assumptions!$C$10)) -> 12.26858 | H12: =2000*EXP(-Assumptions!$C$11*Assumptions!$C$10)*NORMSDIST((LN(2000/Assumptions!$C$7)+(Assumptions!$C$9-Assumptions!$C$11+0.35^2/2)*Assumptions!$C$10)/(0.35*SQRT(Assumptions!$C$10)))-Assumptions!$C$7*EXP(-Assumptions!$C$9*Assumptions!$C$10)*NORMSDIST(((LN(2000/Assumptions!$C$7)+(Assumptions!$C$9-Assumptions!$C$11+0.35^2/2)*Assumptions!$C$10)/(0.35*SQRT(Assumptions!$C$10)))-0.35*SQRT(Assumptions!$C$10)) -> 21.847379 | I12: =2000*EXP(-Assumptions!$C$11*Assumptions!$C$10)*NORMSDIST((LN(2000/Assumptions!$C$7)+(Assumptions!$C$9-Assumptions!$C$11+0.4^2/2)*Assumptions!$C$10)/(0.4*SQRT(Assumptions!$C$10)))-Assumptions!$C$7*EXP(-Assumptions!$C$9*Assumptions!$C$10)*NORMSDIST(((LN(2000/Assumptions!$C$7)+(Assumptions!$C$9-Assumptions!$C$11+0.4^2/2)*Assumptions!$C$10)/(0.4*SQRT(Assumptions!$C$10)))-0.4*SQRT(Assumptions!$C$10)) -> 33.618654 | J12: =2000*EXP(-Assumptions!$C$11*Assumptions!$C$10)*NORMSDIST((LN(2000/Assumptions!$C$7)+(Assumptions!$C$9-Assumptions!$C$11+0.45^2/2)*Assumptions!$C$10)/(0.45*SQRT(Assumptions!$C$10)))-Assumptions!$C$7*EXP(-Assumptions!$C$9*Assumptions!$C$10)*NORMSDIST(((LN(2000/Assumptions!$C$7)+(Assumptions!$C$9-Assumptions!$C$11+0.45^2/2)*Assumptions!$C$10)/(0.45*SQRT(Assumptions!$C$10)))-0.45*SQRT(Assumptions!$C$10)) -> 47.122739 | K12: =2000*EXP(-Assumptions!$C$11*Assumptions!$C$10)*NORMSDIST((LN(2000/Assumptions!$C$7)+(Assumptions!$C$9-Assumptions!$C$11+0.5^2/2)*Assumptions!$C$10)/(0.5*SQRT(Assumptions!$C$10)))-Assumptions!$C$7*EXP(-Assumptions!$C$9*Assumptions!$C$10)*NORMSDIST(((LN(2000/Assumptions!$C$7)+(Assumptions!$C$9-Assumptions!$C$11+0.5^2/2)*Assumptions!$C$10)/(0.5*SQRT(Assumptions!$C$10)))-0.5*SQRT(Assumptions!$C$10)) -> 61.983968
B13: 2050 | C13: =2050*EXP(-Assumptions!$C$11*Assumptions!$C$10)*NORMSDIST((LN(2050/Assumptions!$C$7)+(Assumptions!$C$9-Assumptions!$C$11+0.1^2/2)*Assumptions!$C$10)/(0.1*SQRT(Assumptions!$C$10)))-Assumptions!$C$7*EXP(-Assumptions!$C$9*Assumptions!$C$10)*NORMSDIST(((LN(2050/Assumptions!$C$7)+(Assumptions!$C$9-Assumptions!$C$11+0.1^2/2)*Assumptions!$C$10)/(0.1*SQRT(Assumptions!$C$10)))-0.1*SQRT(Assumptions!$C$10)) -> 0.0029790324 | D13: =2050*EXP(-Assumptions!$C$11*Assumptions!$C$10)*NORMSDIST((LN(2050/Assumptions!$C$7)+(Assumptions!$C$9-Assumptions!$C$11+0.15^2/2)*Assumptions!$C$10)/(0.15*SQRT(Assumptions!$C$10)))-Assumptions!$C$7*EXP(-Assumptions!$C$9*Assumptions!$C$10)*NORMSDIST(((LN(2050/Assumptions!$C$7)+(Assumptions!$C$9-Assumptions!$C$11+0.15^2/2)*Assumptions!$C$10)/(0.15*SQRT(Assumptions!$C$10)))-0.15*SQRT(Assumptions!$C$10)) -> 0.37798345 | E13: =2050*EXP(-Assumptions!$C$11*Assumptions!$C$10)*NORMSDIST((LN(2050/Assumptions!$C$7)+(Assumptions!$C$9-Assumptions!$C$11+0.2^2/2)*Assumptions!$C$10)/(0.2*SQRT(Assumptions!$C$10)))-Assumptions!$C$7*EXP(-Assumptions!$C$9*Assumptions!$C$10)*NORMSDIST(((LN(2050/Assumptions!$C$7)+(Assumptions!$C$9-Assumptions!$C$11+0.2^2/2)*Assumptions!$C$10)/(0.2*SQRT(Assumptions!$C$10)))-0.2*SQRT(Assumptions!$C$10)) -> 2.8390967 | F13: =2050*EXP(-Assumptions!$C$11*Assumptions!$C$10)*NORMSDIST((LN(2050/Assumptions!$C$7)+(Assumptions!$C$9-Assumptions!$C$11+0.25^2/2)*Assumptions!$C$10)/(0.25*SQRT(Assumptions!$C$10)))-Assumptions!$C$7*EXP(-Assumptions!$C$9*Assumptions!$C$10)*NORMSDIST(((LN(2050/Assumptions!$C$7)+(Assumptions!$C$9-Assumptions!$C$11+0.25^2/2)*Assumptions!$C$10)/(0.25*SQRT(Assumptions!$C$10)))-0.25*SQRT(Assumptions!$C$10)) -> 8.6323189 | G13: =2050*EXP(-Assumptions!$C$11*Assumptions!$C$10)*NORMSDIST((LN(2050/Assumptions!$C$7)+(Assumptions!$C$9-Assumptions!$C$11+0.3^2/2)*Assumptions!$C$10)/(0.3*SQRT(Assumptions!$C$10)))-Assumptions!$C$7*EXP(-Assumptions!$C$9*Assumptions!$C$10)*NORMSDIST(((LN(2050/Assumptions!$C$7)+(Assumptions!$C$9-Assumptions!$C$11+0.3^2/2)*Assumptions!$C$10)/(0.3*SQRT(Assumptions!$C$10)))-0.3*SQRT(Assumptions!$C$10)) -> 17.658071 | H13: =2050*EXP(-Assumptions!$C$11*Assumptions!$C$10)*NORMSDIST((LN(2050/Assumptions!$C$7)+(Assumptions!$C$9-Assumptions!$C$11+0.35^2/2)*Assumptions!$C$10)/(0.35*SQRT(Assumptions!$C$10)))-Assumptions!$C$7*EXP(-Assumptions!$C$9*Assumptions!$C$10)*NORMSDIST(((LN(2050/Assumptions!$C$7)+(Assumptions!$C$9-Assumptions!$C$11+0.35^2/2)*Assumptions!$C$10)/(0.35*SQRT(Assumptions!$C$10)))-0.35*SQRT(Assumptions!$C$10)) -> 29.31819 | I13: =2050*EXP(-Assumptions!$C$11*Assumptions!$C$10)*NORMSDIST((LN(2050/Assumptions!$C$7)+(Assumptions!$C$9-Assumptions!$C$11+0.4^2/2)*Assumptions!$C$10)/(0.4*SQRT(Assumptions!$C$10)))-Assumptions!$C$7*EXP(-Assumptions!$C$9*Assumptions!$C$10)*NORMSDIST(((LN(2050/Assumptions!$C$7)+(Assumptions!$C$9-Assumptions!$C$11+0.4^2/2)*Assumptions!$C$10)/(0.4*SQRT(Assumptions!$C$10)))-0.4*SQRT(Assumptions!$C$10)) -> 43.006886 | J13: =2050*EXP(-Assumptions!$C$11*Assumptions!$C$10)*NORMSDIST((LN(2050/Assumptions!$C$7)+(Assumptions!$C$9-Assumptions!$C$11+0.45^2/2)*Assumptions!$C$10)/(0.45*SQRT(Assumptions!$C$10)))-Assumptions!$C$7*EXP(-Assumptions!$C$9*Assumptions!$C$10)*NORMSDIST(((LN(2050/Assumptions!$C$7)+(Assumptions!$C$9-Assumptions!$C$11+0.45^2/2)*Assumptions!$C$10)/(0.45*SQRT(Assumptions!$C$10)))-0.45*SQRT(Assumptions!$C$10)) -> 58.236619 | K13: =2050*EXP(-Assumptions!$C$11*Assumptions!$C$10)*NORMSDIST((LN(2050/Assumptions!$C$7)+(Assumptions!$C$9-Assumptions!$C$11+0.5^2/2)*Assumptions!$C$10)/(0.5*SQRT(Assumptions!$C$10)))-Assumptions!$C$7*EXP(-Assumptions!$C$9*Assumptions!$C$10)*NORMSDIST(((LN(2050/Assumptions!$C$7)+(Assumptions!$C$9-Assumptions!$C$11+0.5^2/2)*Assumptions!$C$10)/(0.5*SQRT(Assumptions!$C$10)))-0.5*SQRT(Assumptions!$C$10)) -> 74.640094
B14: 2100 | C14: =2100*EXP(-Assumptions!$C$11*Assumptions!$C$10)*NORMSDIST((LN(2100/Assumptions!$C$7)+(Assumptions!$C$9-Assumptions!$C$11+0.1^2/2)*Assumptions!$C$10)/(0.1*SQRT(Assumptions!$C$10)))-Assumptions!$C$7*EXP(-Assumptions!$C$9*Assumptions!$C$10)*NORMSDIST(((LN(2100/Assumptions!$C$7)+(Assumptions!$C$9-Assumptions!$C$11+0.1^2/2)*Assumptions!$C$10)/(0.1*SQRT(Assumptions!$C$10)))-0.1*SQRT(Assumptions!$C$10)) -> 0.020097468 | D14: =2100*EXP(-Assumptions!$C$11*Assumptions!$C$10)*NORMSDIST((LN(2100/Assumptions!$C$7)+(Assumptions!$C$9-Assumptions!$C$11+0.15^2/2)*Assumptions!$C$10)/(0.15*SQRT(Assumptions!$C$10)))-Assumptions!$C$7*EXP(-Assumptions!$C$9*Assumptions!$C$10)*NORMSDIST(((LN(2100/Assumptions!$C$7)+(Assumptions!$C$9-Assumptions!$C$11+0.15^2/2)*Assumptions!$C$10)/(0.15*SQRT(Assumptions!$C$10)))-0.15*SQRT(Assumptions!$C$10)) -> 0.98101646 | E14: =2100*EXP(-Assumptions!$C$11*Assumptions!$C$10)*NORMSDIST((LN(2100/Assumptions!$C$7)+(Assumptions!$C$9-Assumptions!$C$11+0.2^2/2)*Assumptions!$C$10)/(0.2*SQRT(Assumptions!$C$10)))-Assumptions!$C$7*EXP(-Assumptions!$C$9*Assumptions!$C$10)*NORMSDIST(((LN(2100/Assumptions!$C$7)+(Assumptions!$C$9-Assumptions!$C$11+0.2^2/2)*Assumptions!$C$10)/(0.2*SQRT(Assumptions!$C$10)))-0.2*SQRT(Assumptions!$C$10)) -> 5.1963157 | F14: =2100*EXP(-Assumptions!$C$11*Assumptions!$C$10)*NORMSDIST((LN(2100/Assumptions!$C$7)+(Assumptions!$C$9-Assumptions!$C$11+0.25^2/2)*Assumptions!$C$10)/(0.25*SQRT(Assumptions!$C$10)))-Assumptions!$C$7*EXP(-Assumptions!$C$9*Assumptions!$C$10)*NORMSDIST(((LN(2100/Assumptions!$C$7)+(Assumptions!$C$9-Assumptions!$C$11+0.25^2/2)*Assumptions!$C$10)/(0.25*SQRT(Assumptions!$C$10)))-0.25*SQRT(Assumptions!$C$10)) -> 13.322473 | G14: =2100*EXP(-Assumptions!$C$11*Assumptions!$C$10)*NORMSDIST((LN(2100/Assumptions!$C$7)+(Assumptions!$C$9-Assumptions!$C$11+0.3^2/2)*Assumptions!$C$10)/(0.3*SQRT(Assumptions!$C$10)))-Assumptions!$C$7*EXP(-Assumptions!$C$9*Assumptions!$C$10)*NORMSDIST(((LN(2100/Assumptions!$C$7)+(Assumptions!$C$9-Assumptions!$C$11+0.3^2/2)*Assumptions!$C$10)/(0.3*SQRT(Assumptions!$C$10)))-0.3*SQRT(Assumptions!$C$10)) -> 24.704988 | H14: =2100*EXP(-Assumptions!$C$11*Assumptions!$C$10)*NORMSDIST((LN(2100/Assumptions!$C$7)+(Assumptions!$C$9-Assumptions!$C$11+0.35^2/2)*Assumptions!$C$10)/(0.35*SQRT(Assumptions!$C$10)))-Assumptions!$C$7*EXP(-Assumptions!$C$9*Assumptions!$C$10)*NORMSDIST(((LN(2100/Assumptions!$C$7)+(Assumptions!$C$9-Assumptions!$C$11+0.35^2/2)*Assumptions!$C$10)/(0.35*SQRT(Assumptions!$C$10)))-0.35*SQRT(Assumptions!$C$10)) -> 38.523484 | I14: =2100*EXP(-Assumptions!$C$11*Assumptions!$C$10)*NORMSDIST((LN(2100/Assumptions!$C$7)+(Assumptions!$C$9-Assumptions!$C$11+0.4^2/2)*Assumptions!$C$10)/(0.4*SQRT(Assumptions!$C$10)))-Assumptions!$C$7*EXP(-Assumptions!$C$9*Assumptions!$C$10)*NORMSDIST(((LN(2100/Assumptions!$C$7)+(Assumptions!$C$9-Assumptions!$C$11+0.4^2/2)*Assumptions!$C$10)/(0.4*SQRT(Assumptions!$C$10)))-0.4*SQRT(Assumptions!$C$10)) -> 54.122245 | J14: =2100*EXP(-Assumptions!$C$11*Assumptions!$C$10)*NORMSDIST((LN(2100/Assumptions!$C$7)+(Assumptions!$C$9-Assumptions!$C$11+0.45^2/2)*Assumptions!$C$10)/(0.45*SQRT(Assumptions!$C$10)))-Assumptions!$C$7*EXP(-Assumptions!$C$9*Assumptions!$C$10)*NORMSDIST(((LN(2100/Assumptions!$C$7)+(Assumptions!$C$9-Assumptions!$C$11+0.45^2/2)*Assumptions!$C$10)/(0.45*SQRT(Assumptions!$C$10)))-0.45*SQRT(Assumptions!$C$10)) -> 71.027322 | K14: =2100*EXP(-Assumptions!$C$11*Assumptions!$C$10)*NORMSDIST((LN(2100/Assumptions!$C$7)+(Assumptions!$C$9-Assumptions!$C$11+0.5^2/2)*Assumptions!$C$10)/(0.5*SQRT(Assumptions!$C$10)))-Assumptions!$C$7*EXP(-Assumptions!$C$9*Assumptions!$C$10)*NORMSDIST(((LN(2100/Assumptions!$C$7)+(Assumptions!$C$9-Assumptions!$C$11+0.5^2/2)*Assumptions!$C$10)/(0.5*SQRT(Assumptions!$C$10)))-0.5*SQRT(Assumptions!$C$10)) -> 88.902899
B15: 2150 | C15: =2150*EXP(-Assumptions!$C$11*Assumptions!$C$10)*NORMSDIST((LN(2150/Assumptions!$C$7)+(Assumptions!$C$9-Assumptions!$C$11+0.1^2/2)*Assumptions!$C$10)/(0.1*SQRT(Assumptions!$C$10)))-Assumptions!$C$7*EXP(-Assumptions!$C$9*Assumptions!$C$10)*NORMSDIST(((LN(2150/Assumptions!$C$7)+(Assumptions!$C$9-Assumptions!$C$11+0.1^2/2)*Assumptions!$C$10)/(0.1*SQRT(Assumptions!$C$10)))-0.1*SQRT(Assumptions!$C$10)) -> 0.10619767 | D15: =2150*EXP(-Assumptions!$C$11*Assumptions!$C$10)*NORMSDIST((LN(2150/Assumptions!$C$7)+(Assumptions!$C$9-Assumptions!$C$11+0.15^2/2)*Assumptions!$C$10)/(0.15*SQRT(Assumptions!$C$10)))-Assumptions!$C$7*EXP(-Assumptions!$C$9*Assumptions!$C$10)*NORMSDIST(((LN(2150/Assumptions!$C$7)+(Assumptions!$C$9-Assumptions!$C$11+0.15^2/2)*Assumptions!$C$10)/(0.15*SQRT(Assumptions!$C$10)))-0.15*SQRT(Assumptions!$C$10)) -> 2.2918916 | E15: =2150*EXP(-Assumptions!$C$11*Assumptions!$C$10)*NORMSDIST((LN(2150/Assumptions!$C$7)+(Assumptions!$C$9-Assumptions!$C$11+0.2^2/2)*Assumptions!$C$10)/(0.2*SQRT(Assumptions!$C$10)))-Assumptions!$C$7*EXP(-Assumptions!$C$9*Assumptions!$C$10)*NORMSDIST(((LN(2150/Assumptions!$C$7)+(Assumptions!$C$9-Assumptions!$C$11+0.2^2/2)*Assumptions!$C$10)/(0.2*SQRT(Assumptions!$C$10)))-0.2*SQRT(Assumptions!$C$10)) -> 8.9717988 | F15: =2150*EXP(-Assumptions!$C$11*Assumptions!$C$10)*NORMSDIST((LN(2150/Assumptions!$C$7)+(Assumptions!$C$9-Assumptions!$C$11+0.25^2/2)*Assumptions!$C$10)/(0.25*SQRT(Assumptions!$C$10)))-Assumptions!$C$7*EXP(-Assumptions!$C$9*Assumptions!$C$10)*NORMSDIST(((LN(2150/Assumptions!$C$7)+(Assumptions!$C$9-Assumptions!$C$11+0.25^2/2)*Assumptions!$C$10)/(0.25*SQRT(Assumptions!$C$10)))-0.25*SQRT(Assumptions!$C$10)) -> 19.808538 | G15: =2150*EXP(-Assumptions!$C$11*Assumptions!$C$10)*NORMSDIST((LN(2150/Assumptions!$C$7)+(Assumptions!$C$9-Assumptions!$C$11+0.3^2/2)*Assumptions!$C$10)/(0.3*SQRT(Assumptions!$C$10)))-Assumptions!$C$7*EXP(-Assumptions!$C$9*Assumptions!$C$10)*NORMSDIST(((LN(2150/Assumptions!$C$7)+(Assumptions!$C$9-Assumptions!$C$11+0.3^2/2)*Assumptions!$C$10)/(0.3*SQRT(Assumptions!$C$10)))-0.3*SQRT(Assumptions!$C$10)) -> 33.674111 | H15: =2150*EXP(-Assumptions!$C$11*Assumptions!$C$10)*NORMSDIST((LN(2150/Assumptions!$C$7)+(Assumptions!$C$9-Assumptions!$C$11+0.35^2/2)*Assumptions!$C$10)/(0.35*SQRT(Assumptions!$C$10)))-Assumptions!$C$7*EXP(-Assumptions!$C$9*Assumptions!$C$10)*NORMSDIST(((LN(2150/Assumptions!$C$7)+(Assumptions!$C$9-Assumptions!$C$11+0.35^2/2)*Assumptions!$C$10)/(0.35*SQRT(Assumptions!$C$10)))-0.35*SQRT(Assumptions!$C$10)) -> 49.644672 | I15: =2150*EXP(-Assumptions!$C$11*Assumptions!$C$10)*NORMSDIST((LN(2150/Assumptions!$C$7)+(Assumptions!$C$9-Assumptions!$C$11+0.4^2/2)*Assumptions!$C$10)/(0.4*SQRT(Assumptions!$C$10)))-Assumptions!$C$7*EXP(-Assumptions!$C$9*Assumptions!$C$10)*NORMSDIST(((LN(2150/Assumptions!$C$7)+(Assumptions!$C$9-Assumptions!$C$11+0.4^2/2)*Assumptions!$C$10)/(0.4*SQRT(Assumptions!$C$10)))-0.4*SQRT(Assumptions!$C$10)) -> 67.085849 | J15: =2150*EXP(-Assumptions!$C$11*Assumptions!$C$10)*NORMSDIST((LN(2150/Assumptions!$C$7)+(Assumptions!$C$9-Assumptions!$C$11+0.45^2/2)*Assumptions!$C$10)/(0.45*SQRT(Assumptions!$C$10)))-Assumptions!$C$7*EXP(-Assumptions!$C$9*Assumptions!$C$10)*NORMSDIST(((LN(2150/Assumptions!$C$7)+(Assumptions!$C$9-Assumptions!$C$11+0.45^2/2)*Assumptions!$C$10)/(0.45*SQRT(Assumptions!$C$10)))-0.45*SQRT(Assumptions!$C$10)) -> 85.573806 | K15: =2150*EXP(-Assumptions!$C$11*Assumptions!$C$10)*NORMSDIST((LN(2150/Assumptions!$C$7)+(Assumptions!$C$9-Assumptions!$C$11+0.5^2/2)*Assumptions!$C$10)/(0.5*SQRT(Assumptions!$C$10)))-Assumptions!$C$7*EXP(-Assumptions!$C$9*Assumptions!$C$10)*NORMSDIST(((LN(2150/Assumptions!$C$7)+(Assumptions!$C$9-Assumptions!$C$11+0.5^2/2)*Assumptions!$C$10)/(0.5*SQRT(Assumptions!$C$10)))-0.5*SQRT(Assumptions!$C$10)) -> 104.82203
B16: 2200 | C16: =2200*EXP(-Assumptions!$C$11*Assumptions!$C$10)*NORMSDIST((LN(2200/Assumptions!$C$7)+(Assumptions!$C$9-Assumptions!$C$11+0.1^2/2)*Assumptions!$C$10)/(0.1*SQRT(Assumptions!$C$10)))-Assumptions!$C$7*EXP(-Assumptions!$C$9*Assumptions!$C$10)*NORMSDIST(((LN(2200/Assumptions!$C$7)+(Assumptions!$C$9-Assumptions!$C$11+0.1^2/2)*Assumptions!$C$10)/(0.1*SQRT(Assumptions!$C$10)))-0.1*SQRT(Assumptions!$C$10)) -> 0.44863746 | D16: =2200*EXP(-Assumptions!$C$11*Assumptions!$C$10)*NORMSDIST((LN(2200/Assumptions!$C$7)+(Assumptions!$C$9-Assumptions!$C$11+0.15^2/2)*Assumptions!$C$10)/(0.15*SQRT(Assumptions!$C$10)))-Assumptions!$C$7*EXP(-Assumptions!$C$9*Assumptions!$C$10)*NORMSDIST(((LN(2200/Assumptions!$C$7)+(Assumptions!$C$9-Assumptions!$C$11+0.15^2/2)*Assumptions!$C$10)/(0.15*SQRT(Assumptions!$C$10)))-0.15*SQRT(Assumptions!$C$10)) -> 4.8634188 | E16: =2200*EXP(-Assumptions!$C$11*Assumptions!$C$10)*NORMSDIST((LN(2200/Assumptions!$C$7)+(Assumptions!$C$9-Assumptions!$C$11+0.2^2/2)*Assumptions!$C$10)/(0.2*SQRT(Assumptions!$C$10)))-Assumptions!$C$7*EXP(-Assumptions!$C$9*Assumptions!$C$10)*NORMSDIST(((LN(2200/Assumptions!$C$7)+(Assumptions!$C$9-Assumptions!$C$11+0.2^2/2)*Assumptions!$C$10)/(0.2*SQRT(Assumptions!$C$10)))-0.2*SQRT(Assumptions!$C$10)) -> 14.68487 | F16: =2200*EXP(-Assumptions!$C$11*Assumptions!$C$10)*NORMSDIST((LN(2200/Assumptions!$C$7)+(Assumptions!$C$9-Assumptions!$C$11+0.25^2/2)*Assumptions!$C$10)/(0.25*SQRT(Assumptions!$C$10)))-Assumptions!$C$7*EXP(-Assumptions!$C$9*Assumptions!$C$10)*NORMSDIST(((LN(2200/Assumptions!$C$7)+(Assumptions!$C$9-Assumptions!$C$11+0.25^2/2)*Assumptions!$C$10)/(0.25*SQRT(Assumptions!$C$10)))-0.25*SQRT(Assumptions!$C$10)) -> 28.461581 | G16: =2200*EXP(-Assumptions!$C$11*Assumptions!$C$10)*NORMSDIST((LN(2200/Assumptions!$C$7)+(Assumptions!$C$9-Assumptions!$C$11+0.3^2/2)*Assumptions!$C$10)/(0.3*SQRT(Assumptions!$C$10)))-Assumptions!$C$7*EXP(-Assumptions!$C$9*Assumptions!$C$10)*NORMSDIST(((LN(2200/Assumptions!$C$7)+(Assumptions!$C$9-Assumptions!$C$11+0.3^2/2)*Assumptions!$C$10)/(0.3*SQRT(Assumptions!$C$10)))-0.3*SQRT(Assumptions!$C$10)) -> 44.810439 | H16: =2200*EXP(-Assumptions!$C$11*Assumptions!$C$10)*NORMSDIST((LN(2200/Assumptions!$C$7)+(Assumptions!$C$9-Assumptions!$C$11+0.35^2/2)*Assumptions!$C$10)/(0.35*SQRT(Assumptions!$C$10)))-Assumptions!$C$7*EXP(-Assumptions!$C$9*Assumptions!$C$10)*NORMSDIST(((LN(2200/Assumptions!$C$7)+(Assumptions!$C$9-Assumptions!$C$11+0.35^2/2)*Assumptions!$C$10)/(0.35*SQRT(Assumptions!$C$10)))-0.35*SQRT(Assumptions!$C$10)) -> 62.83907 | I16: =2200*EXP(-Assumptions!$C$11*Assumptions!$C$10)*NORMSDIST((LN(2200/Assumptions!$C$7)+(Assumptions!$C$9-Assumptions!$C$11+0.4^2/2)*Assumptions!$C$10)/(0.4*SQRT(Assumptions!$C$10)))-Assumptions!$C$7*EXP(-Assumptions!$C$9*Assumptions!$C$10)*NORMSDIST(((LN(2200/Assumptions!$C$7)+(Assumptions!$C$9-Assumptions!$C$11+0.4^2/2)*Assumptions!$C$10)/(0.4*SQRT(Assumptions!$C$10)))-0.4*SQRT(Assumptions!$C$10)) -> 81.996767 | J16: =2200*EXP(-Assumptions!$C$11*Assumptions!$C$10)*NORMSDIST((LN(2200/Assumptions!$C$7)+(Assumptions!$C$9-Assumptions!$C$11+0.45^2/2)*Assumptions!$C$10)/(0.45*SQRT(Assumptions!$C$10)))-Assumptions!$C$7*EXP(-Assumptions!$C$9*Assumptions!$C$10)*NORMSDIST(((LN(2200/Assumptions!$C$7)+(Assumptions!$C$9-Assumptions!$C$11+0.45^2/2)*Assumptions!$C$10)/(0.45*SQRT(Assumptions!$C$10)))-0.45*SQRT(Assumptions!$C$10)) -> 101.93659 | K16: =2200*EXP(-Assumptions!$C$11*Assumptions!$C$10)*NORMSDIST((LN(2200/Assumptions!$C$7)+(Assumptions!$C$9-Assumptions!$C$11+0.5^2/2)*Assumptions!$C$10)/(0.5*SQRT(Assumptions!$C$10)))-Assumptions!$C$7*EXP(-Assumptions!$C$9*Assumptions!$C$10)*NORMSDIST(((LN(2200/Assumptions!$C$7)+(Assumptions!$C$9-Assumptions!$C$11+0.5^2/2)*Assumptions!$C$10)/(0.5*SQRT(Assumptions!$C$10)))-0.5*SQRT(Assumptions!$C$10)) -> 122.43222
B17: 2250 | C17: =2250*EXP(-Assumptions!$C$11*Assumptions!$C$10)*NORMSDIST((LN(2250/Assumptions!$C$7)+(Assumptions!$C$9-Assumptions!$C$11+0.1^2/2)*Assumptions!$C$10)/(0.1*SQRT(Assumptions!$C$10)))-Assumptions!$C$7*EXP(-Assumptions!$C$9*Assumptions!$C$10)*NORMSDIST(((LN(2250/Assumptions!$C$7)+(Assumptions!$C$9-Assumptions!$C$11+0.1^2/2)*Assumptions!$C$10)/(0.1*SQRT(Assumptions!$C$10)))-0.1*SQRT(Assumptions!$C$10)) -> 1.5454667 | D17: =2250*EXP(-Assumptions!$C$11*Assumptions!$C$10)*NORMSDIST((LN(2250/Assumptions!$C$7)+(Assumptions!$C$9-Assumptions!$C$11+0.15^2/2)*Assumptions!$C$10)/(0.15*SQRT(Assumptions!$C$10)))-Assumptions!$C$7*EXP(-Assumptions!$C$9*Assumptions!$C$10)*NORMSDIST(((LN(2250/Assumptions!$C$7)+(Assumptions!$C$9-Assumptions!$C$11+0.15^2/2)*Assumptions!$C$10)/(0.15*SQRT(Assumptions!$C$10)))-0.15*SQRT(Assumptions!$C$10)) -> 9.4541678 | E17: =2250*EXP(-Assumptions!$C$11*Assumptions!$C$10)*NORMSDIST((LN(2250/Assumptions!$C$7)+(Assumptions!$C$9-Assumptions!$C$11+0.2^2/2)*Assumptions!$C$10)/(0.2*SQRT(Assumptions!$C$10)))-Assumptions!$C$7*EXP(-Assumptions!$C$9*Assumptions!$C$10)*NORMSDIST(((LN(2250/Assumptions!$C$7)+(Assumptions!$C$9-Assumptions!$C$11+0.2^2/2)*Assumptions!$C$10)/(0.2*SQRT(Assumptions!$C$10)))-0.2*SQRT(Assumptions!$C$10)) -> 22.891 | F17: =2250*EXP(-Assumptions!$C$11*Assumptions!$C$10)*NORMSDIST((LN(2250/Assumptions!$C$7)+(Assumptions!$C$9-Assumptions!$C$11+0.25^2/2)*Assumptions!$C$10)/(0.25*SQRT(Assumptions!$C$10)))-Assumptions!$C$7*EXP(-Assumptions!$C$9*Assumptions!$C$10)*NORMSDIST(((LN(2250/Assumptions!$C$7)+(Assumptions!$C$9-Assumptions!$C$11+0.25^2/2)*Assumptions!$C$10)/(0.25*SQRT(Assumptions!$C$10)))-0.25*SQRT(Assumptions!$C$10)) -> 39.63118 | G17: =2250*EXP(-Assumptions!$C$11*Assumptions!$C$10)*NORMSDIST((LN(2250/Assumptions!$C$7)+(Assumptions!$C$9-Assumptions!$C$11+0.3^2/2)*Assumptions!$C$10)/(0.3*SQRT(Assumptions!$C$10)))-Assumptions!$C$7*EXP(-Assumptions!$C$9*Assumptions!$C$10)*NORMSDIST(((LN(2250/Assumptions!$C$7)+(Assumptions!$C$9-Assumptions!$C$11+0.3^2/2)*Assumptions!$C$10)/(0.3*SQRT(Assumptions!$C$10)))-0.3*SQRT(Assumptions!$C$10)) -> 58.326541 | H17: =2250*EXP(-Assumptions!$C$11*Assumptions!$C$10)*NORMSDIST((LN(2250/Assumptions!$C$7)+(Assumptions!$C$9-Assumptions!$C$11+0.35^2/2)*Assumptions!$C$10)/(0.35*SQRT(Assumptions!$C$10)))-Assumptions!$C$7*EXP(-Assumptions!$C$9*Assumptions!$C$10)*NORMSDIST(((LN(2250/Assumptions!$C$7)+(Assumptions!$C$9-Assumptions!$C$11+0.35^2/2)*Assumptions!$C$10)/(0.35*SQRT(Assumptions!$C$10)))-0.35*SQRT(Assumptions!$C$10)) -> 78.234225 | I17: =2250*EXP(-Assumptions!$C$11*Assumptions!$C$10)*NORMSDIST((LN(2250/Assumptions!$C$7)+(Assumptions!$C$9-Assumptions!$C$11+0.4^2/2)*Assumptions!$C$10)/(0.4*SQRT(Assumptions!$C$10)))-Assumptions!$C$7*EXP(-Assumptions!$C$9*Assumptions!$C$10)*NORMSDIST(((LN(2250/Assumptions!$C$7)+(Assumptions!$C$9-Assumptions!$C$11+0.4^2/2)*Assumptions!$C$10)/(0.4*SQRT(Assumptions!$C$10)))-0.4*SQRT(Assumptions!$C$10)) -> 98.929776 | J17: =2250*EXP(-Assumptions!$C$11*Assumptions!$C$10)*NORMSDIST((LN(2250/Assumptions!$C$7)+(Assumptions!$C$9-Assumptions!$C$11+0.45^2/2)*Assumptions!$C$10)/(0.45*SQRT(Assumptions!$C$10)))-Assumptions!$C$7*EXP(-Assumptions!$C$9*Assumptions!$C$10)*NORMSDIST(((LN(2250/Assumptions!$C$7)+(Assumptions!$C$9-Assumptions!$C$11+0.45^2/2)*Assumptions!$C$10)/(0.45*SQRT(Assumptions!$C$10)))-0.45*SQRT(Assumptions!$C$10)) -> 120.15711 | K17: =2250*EXP(-Assumptions!$C$11*Assumptions!$C$10)*NORMSDIST((LN(2250/Assumptions!$C$7)+(Assumptions!$C$9-Assumptions!$C$11+0.5^2/2)*Assumptions!$C$10)/(0.5*SQRT(Assumptions!$C$10)))-Assumptions!$C$7*EXP(-Assumptions!$C$9*Assumptions!$C$10)*NORMSDIST(((LN(2250/Assumptions!$C$7)+(Assumptions!$C$9-Assumptions!$C$11+0.5^2/2)*Assumptions!$C$10)/(0.5*SQRT(Assumptions!$C$10)))-0.5*SQRT(Assumptions!$C$10)) -> 141.75345
B18: 2300 | C18: =2300*EXP(-Assumptions!$C$11*Assumptions!$C$10)*NORMSDIST((LN(2300/Assumptions!$C$7)+(Assumptions!$C$9-Assumptions!$C$11+0.1^2/2)*Assumptions!$C$10)/(0.1*SQRT(Assumptions!$C$10)))-Assumptions!$C$7*EXP(-Assumptions!$C$9*Assumptions!$C$10)*NORMSDIST(((LN(2300/Assumptions!$C$7)+(Assumptions!$C$9-Assumptions!$C$11+0.1^2/2)*Assumptions!$C$10)/(0.1*SQRT(Assumptions!$C$10)))-0.1*SQRT(Assumptions!$C$10)) -> 4.4255121 | D18: =2300*EXP(-Assumptions!$C$11*Assumptions!$C$10)*NORMSDIST((LN(2300/Assumptions!$C$7)+(Assumptions!$C$9-Assumptions!$C$11+0.15^2/2)*Assumptions!$C$10)/(0.15*SQRT(Assumptions!$C$10)))-Assumptions!$C$7*EXP(-Assumptions!$C$9*Assumptions!$C$10)*NORMSDIST(((LN(2300/Assumptions!$C$7)+(Assumptions!$C$9-Assumptions!$C$11+0.15^2/2)*Assumptions!$C$10)/(0.15*SQRT(Assumptions!$C$10)))-0.15*SQRT(Assumptions!$C$10)) -> 16.972927 | E18: =2300*EXP(-Assumptions!$C$11*Assumptions!$C$10)*NORMSDIST((LN(2300/Assumptions!$C$7)+(Assumptions!$C$9-Assumptions!$C$11+0.2^2/2)*Assumptions!$C$10)/(0.2*SQRT(Assumptions!$C$10)))-Assumptions!$C$7*EXP(-Assumptions!$C$9*Assumptions!$C$10)*NORMSDIST(((LN(2300/Assumptions!$C$7)+(Assumptions!$C$9-Assumptions!$C$11+0.2^2/2)*Assumptions!$C$10)/(0.2*SQRT(Assumptions!$C$10)))-0.2*SQRT(Assumptions!$C$10)) -> 34.129749 | F18: =2300*EXP(-Assumptions!$C$11*Assumptions!$C$10)*NORMSDIST((LN(2300/Assumptions!$C$7)+(Assumptions!$C$9-Assumptions!$C$11+0.25^2/2)*Assumptions!$C$10)/(0.25*SQRT(Assumptions!$C$10)))-Assumptions!$C$7*EXP(-Assumptions!$C$9*Assumptions!$C$10)*NORMSDIST(((LN(2300/Assumptions!$C$7)+(Assumptions!$C$9-Assumptions!$C$11+0.25^2/2)*Assumptions!$C$10)/(0.25*SQRT(Assumptions!$C$10)))-0.25*SQRT(Assumptions!$C$10)) -> 53.62048 | G18: =2300*EXP(-Assumptions!$C$11*Assumptions!$C$10)*NORMSDIST((LN(2300/Assumptions!$C$7)+(Assumptions!$C$9-Assumptions!$C$11+0.3^2/2)*Assumptions!$C$10)/(0.3*SQRT(Assumptions!$C$10)))-Assumptions!$C$7*EXP(-Assumptions!$C$9*Assumptions!$C$10)*NORMSDIST(((LN(2300/Assumptions!$C$7)+(Assumptions!$C$9-Assumptions!$C$11+0.3^2/2)*Assumptions!$C$10)/(0.3*SQRT(Assumptions!$C$10)))-0.3*SQRT(Assumptions!$C$10)) -> 74.392085 | H18: =2300*EXP(-Assumptions!$C$11*Assumptions!$C$10)*NORMSDIST((LN(2300/Assumptions!$C$7)+(Assumptions!$C$9-Assumptions!$C$11+0.35^2/2)*Assumptions!$C$10)/(0.35*SQRT(Assumptions!$C$10)))-Assumptions!$C$7*EXP(-Assumptions!$C$9*Assumptions!$C$10)*NORMSDIST(((LN(2300/Assumptions!$C$7)+(Assumptions!$C$9-Assumptions!$C$11+0.35^2/2)*Assumptions!$C$10)/(0.35*SQRT(Assumptions!$C$10)))-0.35*SQRT(Assumptions!$C$10)) -> 95.923927 | I18: =2300*EXP(-Assumptions!$C$11*Assumptions!$C$10)*NORMSDIST((LN(2300/Assumptions!$C$7)+(Assumptions!$C$9-Assumptions!$C$11+0.4^2/2)*Assumptions!$C$10)/(0.4*SQRT(Assumptions!$C$10)))-Assumptions!$C$7*EXP(-Assumptions!$C$9*Assumptions!$C$10)*NORMSDIST(((LN(2300/Assumptions!$C$7)+(Assumptions!$C$9-Assumptions!$C$11+0.4^2/2)*Assumptions!$C$10)/(0.4*SQRT(Assumptions!$C$10)))-0.4*SQRT(Assumptions!$C$10)) -> 117.93418 | J18: =2300*EXP(-Assumptions!$C$11*Assumptions!$C$10)*NORMSDIST((LN(2300/Assumptions!$C$7)+(Assumptions!$C$9-Assumptions!$C$11+0.45^2/2)*Assumptions!$C$10)/(0.45*SQRT(Assumptions!$C$10)))-Assumptions!$C$7*EXP(-Assumptions!$C$9*Assumptions!$C$10)*NORMSDIST(((LN(2300/Assumptions!$C$7)+(Assumptions!$C$9-Assumptions!$C$11+0.45^2/2)*Assumptions!$C$10)/(0.45*SQRT(Assumptions!$C$10)))-0.45*SQRT(Assumptions!$C$10)) -> 140.25777 | K18: =2300*EXP(-Assumptions!$C$11*Assumptions!$C$10)*NORMSDIST((LN(2300/Assumptions!$C$7)+(Assumptions!$C$9-Assumptions!$C$11+0.5^2/2)*Assumptions!$C$10)/(0.5*SQRT(Assumptions!$C$10)))-Assumptions!$C$7*EXP(-Assumptions!$C$9*Assumptions!$C$10)*NORMSDIST(((LN(2300/Assumptions!$C$7)+(Assumptions!$C$9-Assumptions!$C$11+0.5^2/2)*Assumptions!$C$10)/(0.5*SQRT(Assumptions!$C$10)))-0.5*SQRT(Assumptions!$C$10)) -> 162.7914
B19: 2350 | C19: =2350*EXP(-Assumptions!$C$11*Assumptions!$C$10)*NORMSDIST((LN(2350/Assumptions!$C$7)+(Assumptions!$C$9-Assumptions!$C$11+0.1^2/2)*Assumptions!$C$10)/(0.1*SQRT(Assumptions!$C$10)))-Assumptions!$C$7*EXP(-Assumptions!$C$9*Assumptions!$C$10)*NORMSDIST(((LN(2350/Assumptions!$C$7)+(Assumptions!$C$9-Assumptions!$C$11+0.1^2/2)*Assumptions!$C$10)/(0.1*SQRT(Assumptions!$C$10)))-0.1*SQRT(Assumptions!$C$10)) -> 10.735678 | D19: =2350*EXP(-Assumptions!$C$11*Assumptions!$C$10)*NORMSDIST((LN(2350/Assumptions!$C$7)+(Assumptions!$C$9-Assumptions!$C$11+0.15^2/2)*Assumptions!$C$10)/(0.15*SQRT(Assumptions!$C$10)))-Assumptions!$C$7*EXP(-Assumptions!$C$9*Assumptions!$C$10)*NORMSDIST(((LN(2350/Assumptions!$C$7)+(Assumptions!$C$9-Assumptions!$C$11+0.15^2/2)*Assumptions!$C$10)/(0.15*SQRT(Assumptions!$C$10)))-0.15*SQRT(Assumptions!$C$10)) -> 28.359048 | E19: =2350*EXP(-Assumptions!$C$11*Assumptions!$C$10)*NORMSDIST((LN(2350/Assumptions!$C$7)+(Assumptions!$C$9-Assumptions!$C$11+0.2^2/2)*Assumptions!$C$10)/(0.2*SQRT(Assumptions!$C$10)))-Assumptions!$C$7*EXP(-Assumptions!$C$9*Assumptions!$C$10)*NORMSDIST(((LN(2350/Assumptions!$C$7)+(Assumptions!$C$9-Assumptions!$C$11+0.2^2/2)*Assumptions!$C$10)/(0.2*SQRT(Assumptions!$C$10)))-0.2*SQRT(Assumptions!$C$10)) -> 48.868265 | F19: =2350*EXP(-Assumptions!$C$11*Assumptions!$C$10)*NORMSDIST((LN(2350/Assumptions!$C$7)+(Assumptions!$C$9-Assumptions!$C$11+0.25^2/2)*Assumptions!$C$10)/(0.25*SQRT(Assumptions!$C$10)))-Assumptions!$C$7*EXP(-Assumptions!$C$9*Assumptions!$C$10)*NORMSDIST(((LN(2350/Assumptions!$C$7)+(Assumptions!$C$9-Assumptions!$C$11+0.25^2/2)*Assumptions!$C$10)/(0.25*SQRT(Assumptions!$C$10)))-0.25*SQRT(Assumptions!$C$10)) -> 70.664858 | G19: =2350*EXP(-Assumptions!$C$11*Assumptions!$C$10)*NORMSDIST((LN(2350/Assumptions!$C$7)+(Assumptions!$C$9-Assumptions!$C$11+0.3^2/2)*Assumptions!$C$10)/(0.3*SQRT(Assumptions!$C$10)))-Assumptions!$C$7*EXP(-Assumptions!$C$9*Assumptions!$C$10)*NORMSDIST(((LN(2350/Assumptions!$C$7)+(Assumptions!$C$9-Assumptions!$C$11+0.3^2/2)*Assumptions!$C$10)/(0.3*SQRT(Assumptions!$C$10)))-0.3*SQRT(Assumptions!$C$10)) -> 93.126379 | H19: =2350*EXP(-Assumptions!$C$11*Assumptions!$C$10)*NORMSDIST((LN(2350/Assumptions!$C$7)+(Assumptions!$C$9-Assumptions!$C$11+0.35^2/2)*Assumptions!$C$10)/(0.35*SQRT(Assumptions!$C$10)))-Assumptions!$C$7*EXP(-Assumptions!$C$9*Assumptions!$C$10)*NORMSDIST(((LN(2350/Assumptions!$C$7)+(Assumptions!$C$9-Assumptions!$C$11+0.35^2/2)*Assumptions!$C$10)/(0.35*SQRT(Assumptions!$C$10)))-0.35*SQRT(Assumptions!$C$10)) -> 115.96606 | I19: =2350*EXP(-Assumptions!$C$11*Assumptions!$C$10)*NORMSDIST((LN(2350/Assumptions!$C$7)+(Assumptions!$C$9-Assumptions!$C$11+0.4^2/2)*Assumptions!$C$10)/(0.4*SQRT(Assumptions!$C$10)))-Assumptions!$C$7*EXP(-Assumptions!$C$9*Assumptions!$C$10)*NORMSDIST(((LN(2350/Assumptions!$C$7)+(Assumptions!$C$9-Assumptions!$C$11+0.4^2/2)*Assumptions!$C$10)/(0.4*SQRT(Assumptions!$C$10)))-0.4*SQRT(Assumptions!$C$10)) -> 139.03369 | J19: =2350*EXP(-Assumptions!$C$11*Assumptions!$C$10)*NORMSDIST((LN(2350/Assumptions!$C$7)+(Assumptions!$C$9-Assumptions!$C$11+0.45^2/2)*Assumptions!$C$10)/(0.45*SQRT(Assumptions!$C$10)))-Assumptions!$C$7*EXP(-Assumptions!$C$9*Assumptions!$C$10)*NORMSDIST(((LN(2350/Assumptions!$C$7)+(Assumptions!$C$9-Assumptions!$C$11+0.45^2/2)*Assumptions!$C$10)/(0.45*SQRT(Assumptions!$C$10)))-0.45*SQRT(Assumptions!$C$10)) -> 162.24248 | K19: =2350*EXP(-Assumptions!$C$11*Assumptions!$C$10)*NORMSDIST((LN(2350/Assumptions!$C$7)+(Assumptions!$C$9-Assumptions!$C$11+0.5^2/2)*Assumptions!$C$10)/(0.5*SQRT(Assumptions!$C$10)))-Assumptions!$C$7*EXP(-Assumptions!$C$9*Assumptions!$C$10)*NORMSDIST(((LN(2350/Assumptions!$C$7)+(Assumptions!$C$9-Assumptions!$C$11+0.5^2/2)*Assumptions!$C$10)/(0.5*SQRT(Assumptions!$C$10)))-0.5*SQRT(Assumptions!$C$10)) -> 185.53824
